Workbook

Sheet Plan
A1: ASCENDRA BIO — Commission Plan Specification
A2: Retroactive whole-amount climb: the commission rate is determined by month-to-date sales and applied to ALL sales for the period. Crossing each of 15 status tiers triggers a one-time bonus.
A4: PLAN PARAMETERS · configurable values (admin portal)
A5: Starting Rate (first $10K band) | C5: 0.08 | D5: Rate applied when sales are in the first $10K increment (band 1).
A6: Rate at $1,000,000 | C6: 0.14 | D6: Target rate when sales reach $1M. Rate interpolates linearly between Starting Rate and this value across $0–$1M.
A7: Rate at $2,000,000 | C7: 0.15 | D7: Target rate when sales reach $2M. Rate interpolates linearly between Rate@$1M and this value across $1M–$2M. Plateaus at this rate above $2M.
A8: Checkpoint Increment | C8: 10000 | D8: Size of each rate-climb band ($10,000).
A11: STATUS TIERS · configurable list (admin portal)
A12: Tier ID | B12: Status Name | C12: Threshold (sales reach ≥ $) | D12: Crossing Bonus ($)
A13: 1 | B13: Associate | C13: 0 | D13: 0 | F13: Tier 1 (Associate) has a $0 threshold and no bonus — it represents the starting state. Tiers 2–15 are crossed in order as month-to-date sales reach each threshold; the crossing bonus pays once per period.
A14: 2 | B14: Account Executive | C14: 50000 | D14: 1000
A15: 3 | B15: Senior Account Executive | C15: 130000 | D15: 1500
A16: 4 | B16: Account Director | C16: 230000 | D16: 2000
A17: 5 | B17: Senior Account Director | C17: 350000 | D17: 2500
A18: 6 | B18: Sales Director | C18: 500000 | D18: 3000
A19: 7 | B19: Senior Sales Director | C19: 700000 | D19: 4000
A20: 8 | B20: Vice President | C20: 950000 | D20: 5000
A21: 9 | B21: President's Circle | C21: 1250000 | D21: 7500
A22: 10 | B22: Chairman's Circle | C22: 1600000 | D22: 10000
A23: 11 | B23: Pinnacle | C23: 2000000 | D23: 15000
A25: CALCULATION LOGIC · for backend implementation
A26: Step | B26: Pseudocode
A27: 1. Determine band | B27: band = MAX(1, CEILING(sales / checkpoint_increment))
A28: 2. Compute commission rate | B28: IF band ≤ 100: rate = starting_rate + (rate_at_1m - starting_rate) × (band - 1) / 99
B29: ELSE IF band ≤ 200: rate = rate_at_1m + (rate_at_2m - rate_at_1m) × (band - 100) / 100
B30: ELSE: rate = rate_at_2m
A31: 3. Commission | B31: commission = sales × rate
A32: 4. Sum bonuses earned | B32: bonus_total = SUM(bonus[i] FOR i IN tiers WHERE threshold[i] ≤ sales)
A33: 5. Total payout | B33: total_payout = commission + bonus_total
A34: 6. Effective rate (display) | B34: effective_rate = total_payout / sales (when sales > 0)
A35: 7. Current status | B35: status = name of highest-id tier where threshold ≤ sales
A38: VERIFICATION TABLE · expected outputs for unit testing
A39: Sales (input) | B39: Status | C39: Rate | D39: Commission | E39: Bonus | F39: Total Payout | G39: Effective Rate
A40: 0 | B40: =IF(A40=0,INDEX($B$13:$B$23,1),INDEX($B$13:$B$23,MATCH(A40,$C$13:$C$23,1))) -> Associate | C40: =IF(A40=0,$C$5,IF(MAX(1,CEILING(A40/$C$8,1))<=100,$C$5+($C$6-$C$5)*(MAX(1,CEILING(A40/$C$8,1))-1)/99,IF(MAX(1,CEILING(A40/$C$8,1))<=200,$C$6+($C$7-$C$6)*(MAX(1,CEILING(A40/$C$8,1))-100)/100,$C$7))) -> 0.08 | D40: =A40*C40 -> 0 | E40: =SUMPRODUCT((A40>=$C$13:$C$23)*$D$13:$D$23) -> 0 | F40: =D40+E40 -> 0 | G40: =IF(A40=0,"—",F40/A40) -> —
A41: 10000 | B41: =IF(A41=0,INDEX($B$13:$B$23,1),INDEX($B$13:$B$23,MATCH(A41,$C$13:$C$23,1))) -> Associate | C41: =IF(A41=0,$C$5,IF(MAX(1,CEILING(A41/$C$8,1))<=100,$C$5+($C$6-$C$5)*(MAX(1,CEILING(A41/$C$8,1))-1)/99,IF(MAX(1,CEILING(A41/$C$8,1))<=200,$C$6+($C$7-$C$6)*(MAX(1,CEILING(A41/$C$8,1))-100)/100,$C$7))) -> 0.08 | D41: =A41*C41 -> 800 | E41: =SUMPRODUCT((A41>=$C$13:$C$23)*$D$13:$D$23) -> 0 | F41: =D41+E41 -> 800 | G41: =IF(A41=0,"—",F41/A41) -> 0.08
A42: 50000 | B42: =IF(A42=0,INDEX($B$13:$B$23,1),INDEX($B$13:$B$23,MATCH(A42,$C$13:$C$23,1))) -> Account Executive | C42: =IF(A42=0,$C$5,IF(MAX(1,CEILING(A42/$C$8,1))<=100,$C$5+($C$6-$C$5)*(MAX(1,CEILING(A42/$C$8,1))-1)/99,IF(MAX(1,CEILING(A42/$C$8,1))<=200,$C$6+($C$7-$C$6)*(MAX(1,CEILING(A42/$C$8,1))-100)/100,$C$7))) -> 0.082424242 | D42: =A42*C42 -> 4121.2121 | E42: =SUMPRODUCT((A42>=$C$13:$C$23)*$D$13:$D$23) -> 1000 | F42: =D42+E42 -> 5121.2121 | G42: =IF(A42=0,"—",F42/A42) -> 0.10242424
A43: 100000 | B43: =IF(A43=0,INDEX($B$13:$B$23,1),INDEX($B$13:$B$23,MATCH(A43,$C$13:$C$23,1))) -> Account Executive | C43: =IF(A43=0,$C$5,IF(MAX(1,CEILING(A43/$C$8,1))<=100,$C$5+($C$6-$C$5)*(MAX(1,CEILING(A43/$C$8,1))-1)/99,IF(MAX(1,CEILING(A43/$C$8,1))<=200,$C$6+($C$7-$C$6)*(MAX(1,CEILING(A43/$C$8,1))-100)/100,$C$7))) -> 0.085454545 | D43: =A43*C43 -> 8545.4545 | E43: =SUMPRODUCT((A43>=$C$13:$C$23)*$D$13:$D$23) -> 1000 | F43: =D43+E43 -> 9545.4545 | G43: =IF(A43=0,"—",F43/A43) -> 0.095454545
A44: 130000 | B44: =IF(A44=0,INDEX($B$13:$B$23,1),INDEX($B$13:$B$23,MATCH(A44,$C$13:$C$23,1))) -> Senior Account Executive | C44: =IF(A44=0,$C$5,IF(MAX(1,CEILING(A44/$C$8,1))<=100,$C$5+($C$6-$C$5)*(MAX(1,CEILING(A44/$C$8,1))-1)/99,IF(MAX(1,CEILING(A44/$C$8,1))<=200,$C$6+($C$7-$C$6)*(MAX(1,CEILING(A44/$C$8,1))-100)/100,$C$7))) -> 0.087272727 | D44: =A44*C44 -> 11345.455 | E44: =SUMPRODUCT((A44>=$C$13:$C$23)*$D$13:$D$23) -> 2500 | F44: =D44+E44 -> 13845.455 | G44: =IF(A44=0,"—",F44/A44) -> 0.1065035
A45: 230000 | B45: =IF(A45=0,INDEX($B$13:$B$23,1),INDEX($B$13:$B$23,MATCH(A45,$C$13:$C$23,1))) -> Account Director | C45: =IF(A45=0,$C$5,IF(MAX(1,CEILING(A45/$C$8,1))<=100,$C$5+($C$6-$C$5)*(MAX(1,CEILING(A45/$C$8,1))-1)/99,IF(MAX(1,CEILING(A45/$C$8,1))<=200,$C$6+($C$7-$C$6)*(MAX(1,CEILING(A45/$C$8,1))-100)/100,$C$7))) -> 0.093333333 | D45: =A45*C45 -> 21466.667 | E45: =SUMPRODUCT((A45>=$C$13:$C$23)*$D$13:$D$23) -> 4500 | F45: =D45+E45 -> 25966.667 | G45: =IF(A45=0,"—",F45/A45) -> 0.11289855
A46: 350000 | B46: =IF(A46=0,INDEX($B$13:$B$23,1),INDEX($B$13:$B$23,MATCH(A46,$C$13:$C$23,1))) -> Senior Account Director | C46: =IF(A46=0,$C$5,IF(MAX(1,CEILING(A46/$C$8,1))<=100,$C$5+($C$6-$C$5)*(MAX(1,CEILING(A46/$C$8,1))-1)/99,IF(MAX(1,CEILING(A46/$C$8,1))<=200,$C$6+($C$7-$C$6)*(MAX(1,CEILING(A46/$C$8,1))-100)/100,$C$7))) -> 0.10060606 | D46: =A46*C46 -> 35212.121 | E46: =SUMPRODUCT((A46>=$C$13:$C$23)*$D$13:$D$23) -> 7000 | F46: =D46+E46 -> 42212.121 | G46: =IF(A46=0,"—",F46/A46) -> 0.12060606
...

Sheet Rep Tracker
A1: Rep Tracker
A2: Sample dashboard view for a rep. Edit the yellow Month-to-Date Sales cell to recalculate.
A4: Rep Name | B4: Jordan Rivera
A5: Month-to-Date Sales | B5: 52000
A7: WHERE YOU ARE NOW
A8: Current Status | B8: {=INDEX(Plan!$B$13:$B$23,MATCH($B$5,Plan!$C$13:$C$23,1))} -> Account Executive
A9: Current Rate (applies to ALL sales) | B9: =IF(MAX(1,CEILING($B$5/Plan!$C$8,1))<=100,Plan!$C$5+(Plan!$C$6-Plan!$C$5)*(MAX(1,CEILING($B$5/Plan!$C$8,1))-1)/99,IF(MAX(1,CEILING($B$5/Plan!$C$8,1))<=200,Plan!$C$6+(Plan!$C$7-Plan!$C$6)*(MAX(1,CEILING($B$5/Plan!$C$8,1))-100)/100,Plan!$C$7)) -> 0.083030303
A10: Commission (Sales × Current Rate) | B10: =($B$5*IF(MAX(1,CEILING($B$5/Plan!$C$8,1))<=100,Plan!$C$5+(Plan!$C$6-Plan!$C$5)*(MAX(1,CEILING($B$5/Plan!$C$8,1))-1)/99,IF(MAX(1,CEILING($B$5/Plan!$C$8,1))<=200,Plan!$C$6+(Plan!$C$7-Plan!$C$6)*(MAX(1,CEILING($B$5/Plan!$C$8,1))-100)/100,Plan!$C$7))) -> 4317.5758
A11: Status Bonuses Earned | B11: =SUMPRODUCT(($B$5>=Plan!$C$13:$C$23)*Plan!$D$13:$D$23) -> 1000
A12: TOTAL PAYOUT | B12: =(($B$5*IF(MAX(1,CEILING($B$5/Plan!$C$8,1))<=100,Plan!$C$5+(Plan!$C$6-Plan!$C$5)*(MAX(1,CEILING($B$5/Plan!$C$8,1))-1)/99,IF(MAX(1,CEILING($B$5/Plan!$C$8,1))<=200,Plan!$C$6+(Plan!$C$7-Plan!$C$6)*(MAX(1,CEILING($B$5/Plan!$C$8,1))-100)/100,Plan!$C$7)))+SUMPRODUCT(($B$5>=Plan!$C$13:$C$23)*Plan!$D$13:$D$23)) -> 5317.5758
A13: Effective Rate | B13: =IF($B$5=0,0,(($B$5*IF(MAX(1,CEILING($B$5/Plan!$C$8,1))<=100,Plan!$C$5+(Plan!$C$6-Plan!$C$5)*(MAX(1,CEILING($B$5/Plan!$C$8,1))-1)/99,IF(MAX(1,CEILING($B$5/Plan!$C$8,1))<=200,Plan!$C$6+(Plan!$C$7-Plan!$C$6)*(MAX(1,CEILING($B$5/Plan!$C$8,1))-100)/100,Plan!$C$7)))+SUMPRODUCT(($B$5>=Plan!$C$13:$C$23)*Plan!$D$13:$D$23))/$B$5) -> 0.10226107
A15: PROGRESS TO NEXT STATUS
A16: Next Status | B16: {=IF(MATCH($B$5,Plan!$C$13:$C$23,1)=11,"★ Top tier",INDEX(Plan!$B$13:$B$23,MATCH($B$5,Plan!$C$13:$C$23,1)+1))} -> Senior Account Executive
A17: Progress | B17: {=IF(MATCH($B$5,Plan!$C$13:$C$23,1)=11,REPT("█",20),REPT("█",ROUND(IF(MATCH($B$5,Plan!$C$13:$C$23,1)=11,1,MIN(1,MAX(0,($B$5-INDEX(Plan!$C$13:$C$23,MATCH($B$5,Plan!$C$13:$C$23,1)))/(IF(MATCH($B$5,Plan!$C$13:$C$23,1)=11,0,INDEX(Plan!$C$13:$C$23,MATCH($B$5,Plan!$C$13:$C$23,1)+1))-INDEX(Plan!$C$13:$C$23,MATCH($B$5,Plan!$C$13:$C$23,1))))))*20,0))&REPT("░",20-ROUND(IF(MATCH($B$5,Plan!$C$13:$C$23,1)=11,1,MIN(1,MAX(0,($B$5-INDEX(Plan!$C$13:$C$23,MATCH($B$5,Plan!$C$13:$C$23,1)))/(IF(MATCH($B$5,Plan!$C$13:$C$23,1)=11,0,INDEX(Plan!$C$13:$C$23,MATCH($B$5,Plan!$C$13:$C$23,1)+1))-INDEX(Plan!$C$13:$C$23,MATCH($B$5,Plan!$C$13:$C$23,1))))))*20,0)))} -> █░░░░░░░░░░░░░░░░░░░
A18: Sales to Next Status | B18: {=IF(MATCH($B$5,Plan!$C$13:$C$23,1)=11,"— at top",IF(MATCH($B$5,Plan!$C$13:$C$23,1)=11,0,IF(MATCH($B$5,Plan!$C$13:$C$23,1)=11,0,INDEX(Plan!$C$13:$C$23,MATCH($B$5,Plan!$C$13:$C$23,1)+1))-$B$5))} -> 78000
A19: Bonus Waiting There | B19: {=IF(MATCH($B$5,Plan!$C$13:$C$23,1)=11,0,INDEX(Plan!$D$13:$D$23,MATCH($B$5,Plan!$C$13:$C$23,1)+1))} -> 1500
A20: {=IF(MATCH($B$5,Plan!$C$13:$C$23,1)=11,"🏆 "&$B$4&" has reached PINNACLE status — the top of the plan!",$B$4&", you are "&TEXT(IF(MATCH($B$5,Plan!$C$13:$C$23,1)=11,0,IF(MATCH($B$5,Plan!$C$13:$C$23,1)=11,0,INDEX(Plan!$C$13:$C$23,MATCH($B$5,Plan!$C$13:$C$23,1)+1))-$B$5),"$#,##0")&" from "&INDEX(Plan!$B$13:$B$23,MATCH($B$5,Plan!$C$13:$C$23,1)+1)&" — unlocking a "&TEXT(INDEX(Plan!$D$13:$D$23,MATCH($B$5,Plan!$C$13:$C$23,1)+1),"$#,##0")&" bonus.")} -> Jordan Rivera, you are $78,000 from Senior Account Executive — unlocking a $1,500 bonus.
A22: MILESTONE FORECAST · what you'd earn at the next 5 status levels
A23: Status | B23: Sales Target | C23: Total Payout at That Level | D23: More $ Than Now | E23: Sales To Get There
A24: {=IF(((MATCH($B$5,Plan!$C$13:$C$23,1)+1)>11),"— at top",INDEX(Plan!$B$13:$B$23,(MATCH($B$5,Plan!$C$13:$C$23,1)+1)))} -> Senior Account Executive | B24: {=IF(((MATCH($B$5,Plan!$C$13:$C$23,1)+1)>11),"",INDEX(Plan!$C$13:$C$23,MIN((MATCH($B$5,Plan!$C$13:$C$23,1)+1),11)))} -> 130000 | C24: {=IF(((MATCH($B$5,Plan!$C$13:$C$23,1)+1)>11),"",(INDEX(Plan!$C$13:$C$23,MIN((MATCH($B$5,Plan!$C$13:$C$23,1)+1),11))*IF(MAX(1,CEILING(INDEX(Plan!$C$13:$C$23,MIN((MATCH($B$5,Plan!$C$13:$C$23,1)+1),11))/Plan!$C$8,1))<=100,Plan!$C$5+(Plan!$C$6-Plan!$C$5)*(MAX(1,CEILING(INDEX(Plan!$C$13:$C$23,MIN((MATCH($B$5,Plan!$C$13:$C$23,1)+1),11))/Plan!$C$8,1))-1)/99,IF(MAX(1,CEILING(INDEX(Plan!$C$13:$C$23,MIN((MATCH($B$5,Plan!$C$13:$C$23,1)+1),11))/Plan!$C$8,1))<=200,Plan!$C$6+(Plan!$C$7-Plan!$C$6)*(MAX(1,CEILING(INDEX(Plan!$C$13:$C$23,MIN((MATCH($B$5,Plan!$C$13:$C$23,1)+1),11))/Plan!$C$8,1))-100)/100,Plan!$C$7))+SUMPRODUCT((INDEX(Plan!$C$13:$C$23,MIN((MATCH($B$5,Plan!$C$13:$C$23,1)+1),11))>=Plan!$C$13:$C$23)*Plan!$D$13:$D$23)))} -> 13845.455 | D24: {=IF(((MATCH($B$5,Plan!$C$13:$C$23,1)+1)>11),"",(INDEX(Plan!$C$13:$C$23,MIN((MATCH($B$5,Plan!$C$13:$C$23,1)+1),11))*IF(MAX(1,CEILING(INDEX(Plan!$C$13:$C$23,MIN((MATCH($B$5,Plan!$C$13:$C$23,1)+1),11))/Plan!$C$8,1))<=100,Plan!$C$5+(Plan!$C$6-Plan!$C$5)*(MAX(1,CEILING(INDEX(Plan!$C$13:$C$23,MIN((MATCH($B$5,Plan!$C$13:$C$23,1)+1),11))/Plan!$C$8,1))-1)/99,IF(MAX(1,CEILING(INDEX(Plan!$C$13:$C$23,MIN((MATCH($B$5,Plan!$C$13:$C$23,1)+1),11))/Plan!$C$8,1))<=200,Plan!$C$6+(Plan!$C$7-Plan!$C$6)*(MAX(1,CEILING(INDEX(Plan!$C$13:$C$23,MIN((MATCH($B$5,Plan!$C$13:$C$23,1)+1),11))/Plan!$C$8,1))-100)/100,Plan!$C$7))+SUMPRODUCT((INDEX(Plan!$C$13:$C$23,MIN((MATCH($B$5,Plan!$C$13:$C$23,1)+1),11))>=Plan!$C$13:$C$23)*Plan!$D$13:$D$23))-(($B$5*IF(MAX(1,CEILING($B$5/Plan!$C$8,1))<=100,Plan!$C$5+(Plan!$C$6-Plan!$C$5)*(MAX(1,CEILING($B$5/Plan!$C$8,1))-1)/99,IF(MAX(1,CEILING($B$5/Plan!$C$8,1))<=200,Plan!$C$6+(Plan!$C$7-Plan!$C$6)*(MAX(1,CEILING($B$5/Plan!$C$8,1))-100)/100,Plan!$C$7)))+SUMPRODUCT(($B$5>=Plan!$C$13:$C$23)*Plan!$D$13:$D$23)))} -> 8527.8788 | E24: {=IF(((MATCH($B$5,Plan!$C$13:$C$23,1)+1)>11),"",INDEX(Plan!$C$13:$C$23,MIN((MATCH($B$5,Plan!$C$13:$C$23,1)+1),11))-$B$5)} -> 78000
A25: {=IF(((MATCH($B$5,Plan!$C$13:$C$23,1)+2)>11),"— at top",INDEX(Plan!$B$13:$B$23,(MATCH($B$5,Plan!$C$13:$C$23,1)+2)))} -> Account Director | B25: {=IF(((MATCH($B$5,Plan!$C$13:$C$23,1)+2)>11),"",INDEX(Plan!$C$13:$C$23,MIN((MATCH($B$5,Plan!$C$13:$C$23,1)+2),11)))} -> 230000 | C25: {=IF(((MATCH($B$5,Plan!$C$13:$C$23,1)+2)>11),"",(INDEX(Plan!$C$13:$C$23,MIN((MATCH($B$5,Plan!$C$13:$C$23,1)+2),11))*IF(MAX(1,CEILING(INDEX(Plan!$C$13:$C$23,MIN((MATCH($B$5,Plan!$C$13:$C$23,1)+2),11))/Plan!$C$8,1))<=100,Plan!$C$5+(Plan!$C$6-Plan!$C$5)*(MAX(1,CEILING(INDEX(Plan!$C$13:$C$23,MIN((MATCH($B$5,Plan!$C$13:$C$23,1)+2),11))/Plan!$C$8,1))-1)/99,IF(MAX(1,CEILING(INDEX(Plan!$C$13:$C$23,MIN((MATCH($B$5,Plan!$C$13:$C$23,1)+2),11))/Plan!$C$8,1))<=200,Plan!$C$6+(Plan!$C$7-Plan!$C$6)*(MAX(1,CEILING(INDEX(Plan!$C$13:$C$23,MIN((MATCH($B$5,Plan!$C$13:$C$23,1)+2),11))/Plan!$C$8,1))-100)/100,Plan!$C$7))+SUMPRODUCT((INDEX(Plan!$C$13:$C$23,MIN((MATCH($B$5,Plan!$C$13:$C$23,1)+2),11))>=Plan!$C$13:$C$23)*Plan!$D$13:$D$23)))} -> 25966.667 | D25: {=IF(((MATCH($B$5,Plan!$C$13:$C$23,1)+2)>11),"",(INDEX(Plan!$C$13:$C$23,MIN((MATCH($B$5,Plan!$C$13:$C$23,1)+2),11))*IF(MAX(1,CEILING(INDEX(Plan!$C$13:$C$23,MIN((MATCH($B$5,Plan!$C$13:$C$23,1)+2),11))/Plan!$C$8,1))<=100,Plan!$C$5+(Plan!$C$6-Plan!$C$5)*(MAX(1,CEILING(INDEX(Plan!$C$13:$C$23,MIN((MATCH($B$5,Plan!$C$13:$C$23,1)+2),11))/Plan!$C$8,1))-1)/99,IF(MAX(1,CEILING(INDEX(Plan!$C$13:$C$23,MIN((MATCH($B$5,Plan!$C$13:$C$23,1)+2),11))/Plan!$C$8,1))<=200,Plan!$C$6+(Plan!$C$7-Plan!$C$6)*(MAX(1,CEILING(INDEX(Plan!$C$13:$C$23,MIN((MATCH($B$5,Plan!$C$13:$C$23,1)+2),11))/Plan!$C$8,1))-100)/100,Plan!$C$7))+SUMPRODUCT((INDEX(Plan!$C$13:$C$23,MIN((MATCH($B$5,Plan!$C$13:$C$23,1)+2),11))>=Plan!$C$13:$C$23)*Plan!$D$13:$D$23))-(($B$5*IF(MAX(1,CEILING($B$5/Plan!$C$8,1))<=100,Plan!$C$5+(Plan!$C$6-Plan!$C$5)*(MAX(1,CEILING($B$5/Plan!$C$8,1))-1)/99,IF(MAX(1,CEILING($B$5/Plan!$C$8,1))<=200,Plan!$C$6+(Plan!$C$7-Plan!$C$6)*(MAX(1,CEILING($B$5/Plan!$C$8,1))-100)/100,Plan!$C$7)))+SUMPRODUCT(($B$5>=Plan!$C$13:$C$23)*Plan!$D$13:$D$23)))} -> 20649.091 | E25: {=IF(((MATCH($B$5,Plan!$C$13:$C$23,1)+2)>11),"",INDEX(Plan!$C$13:$C$23,MIN((MATCH($B$5,Plan!$C$13:$C$23,1)+2),11))-$B$5)} -> 178000
A26: {=IF(((MATCH($B$5,Plan!$C$13:$C$23,1)+3)>11),"— at top",INDEX(Plan!$B$13:$B$23,(MATCH($B$5,Plan!$C$13:$C$23,1)+3)))} -> Senior Account Director | B26: {=IF(((MATCH($B$5,Plan!$C$13:$C$23,1)+3)>11),"",INDEX(Plan!$C$13:$C$23,MIN((MATCH($B$5,Plan!$C$13:$C$23,1)+3),11)))} -> 350000 | C26: {=IF(((MATCH($B$5,Plan!$C$13:$C$23,1)+3)>11),"",(INDEX(Plan!$C$13:$C$23,MIN((MATCH($B$5,Plan!$C$13:$C$23,1)+3),11))*IF(MAX(1,CEILING(INDEX(Plan!$C$13:$C$23,MIN((MATCH($B$5,Plan!$C$13:$C$23,1)+3),11))/Plan!$C$8,1))<=100,Plan!$C$5+(Plan!$C$6-Plan!$C$5)*(MAX(1,CEILING(INDEX(Plan!$C$13:$C$23,MIN((MATCH($B$5,Plan!$C$13:$C$23,1)+3),11))/Plan!$C$8,1))-1)/99,IF(MAX(1,CEILING(INDEX(Plan!$C$13:$C$23,MIN((MATCH($B$5,Plan!$C$13:$C$23,1)+3),11))/Plan!$C$8,1))<=200,Plan!$C$6+(Plan!$C$7-Plan!$C$6)*(MAX(1,CEILING(INDEX(Plan!$C$13:$C$23,MIN((MATCH($B$5,Plan!$C$13:$C$23,1)+3),11))/Plan!$C$8,1))-100)/100,Plan!$C$7))+SUMPRODUCT((INDEX(Plan!$C$13:$C$23,MIN((MATCH($B$5,Plan!$C$13:$C$23,1)+3),11))>=Plan!$C$13:$C$23)*Plan!$D$13:$D$23)))} -> 42212.121 | D26: {=IF(((MATCH($B$5,Plan!$C$13:$C$23,1)+3)>11),"",(INDEX(Plan!$C$13:$C$23,MIN((MATCH($B$5,Plan!$C$13:$C$23,1)+3),11))*IF(MAX(1,CEILING(INDEX(Plan!$C$13:$C$23,MIN((MATCH($B$5,Plan!$C$13:$C$23,1)+3),11))/Plan!$C$8,1))<=100,Plan!$C$5+(Plan!$C$6-Plan!$C$5)*(MAX(1,CEILING(INDEX(Plan!$C$13:$C$23,MIN((MATCH($B$5,Plan!$C$13:$C$23,1)+3),11))/Plan!$C$8,1))-1)/99,IF(MAX(1,CEILING(INDEX(Plan!$C$13:$C$23,MIN((MATCH($B$5,Plan!$C$13:$C$23,1)+3),11))/Plan!$C$8,1))<=200,Plan!$C$6+(Plan!$C$7-Plan!$C$6)*(MAX(1,CEILING(INDEX(Plan!$C$13:$C$23,MIN((MATCH($B$5,Plan!$C$13:$C$23,1)+3),11))/Plan!$C$8,1))-100)/100,Plan!$C$7))+SUMPRODUCT((INDEX(Plan!$C$13:$C$23,MIN((MATCH($B$5,Plan!$C$13:$C$23,1)+3),11))>=Plan!$C$13:$C$23)*Plan!$D$13:$D$23))-(($B$5*IF(MAX(1,CEILING($B$5/Plan!$C$8,1))<=100,Plan!$C$5+(Plan!$C$6-Plan!$C$5)*(MAX(1,CEILING($B$5/Plan!$C$8,1))-1)/99,IF(MAX(1,CEILING($B$5/Plan!$C$8,1))<=200,Plan!$C$6+(Plan!$C$7-Plan!$C$6)*(MAX(1,CEILING($B$5/Plan!$C$8,1))-100)/100,Plan!$C$7)))+SUMPRODUCT(($B$5>=Plan!$C$13:$C$23)*Plan!$D$13:$D$23)))} -> 36894.545 | E26: {=IF(((MATCH($B$5,Plan!$C$13:$C$23,1)+3)>11),"",INDEX(Plan!$C$13:$C$23,MIN((MATCH($B$5,Plan!$C$13:$C$23,1)+3),11))-$B$5)} -> 298000
A27: {=IF(((MATCH($B$5,Plan!$C$13:$C$23,1)+4)>11),"— at top",INDEX(Plan!$B$13:$B$23,(MATCH($B$5,Plan!$C$13:$C$23,1)+4)))} -> Sales Director | B27: {=IF(((MATCH($B$5,Plan!$C$13:$C$23,1)+4)>11),"",INDEX(Plan!$C$13:$C$23,MIN((MATCH($B$5,Plan!$C$13:$C$23,1)+4),11)))} -> 500000 | C27: {=IF(((MATCH($B$5,Plan!$C$13:$C$23,1)+4)>11),"",(INDEX(Plan!$C$13:$C$23,MIN((MATCH($B$5,Plan!$C$13:$C$23,1)+4),11))*IF(MAX(1,CEILING(INDEX(Plan!$C$13:$C$23,MIN((MATCH($B$5,Plan!$C$13:$C$23,1)+4),11))/Plan!$C$8,1))<=100,Plan!$C$5+(Plan!$C$6-Plan!$C$5)*(MAX(1,CEILING(INDEX(Plan!$C$13:$C$23,MIN((MATCH($B$5,Plan!$C$13:$C$23,1)+4),11))/Plan!$C$8,1))-1)/99,IF(MAX(1,CEILING(INDEX(Plan!$C$13:$C$23,MIN((MATCH($B$5,Plan!$C$13:$C$23,1)+4),11))/Plan!$C$8,1))<=200,Plan!$C$6+(Plan!$C$7-Plan!$C$6)*(MAX(1,CEILING(INDEX(Plan!$C$13:$C$23,MIN((MATCH($B$5,Plan!$C$13:$C$23,1)+4),11))/Plan!$C$8,1))-100)/100,Plan!$C$7))+SUMPRODUCT((INDEX(Plan!$C$13:$C$23,MIN((MATCH($B$5,Plan!$C$13:$C$23,1)+4),11))>=Plan!$C$13:$C$23)*Plan!$D$13:$D$23)))} -> 64848.485 | D27: {=IF(((MATCH($B$5,Plan!$C$13:$C$23,1)+4)>11),"",(INDEX(Plan!$C$13:$C$23,MIN((MATCH($B$5,Plan!$C$13:$C$23,1)+4),11))*IF(MAX(1,CEILING(INDEX(Plan!$C$13:$C$23,MIN((MATCH($B$5,Plan!$C$13:$C$23,1)+4),11))/Plan!$C$8,1))<=100,Plan!$C$5+(Plan!$C$6-Plan!$C$5)*(MAX(1,CEILING(INDEX(Plan!$C$13:$C$23,MIN((MATCH($B$5,Plan!$C$13:$C$23,1)+4),11))/Plan!$C$8,1))-1)/99,IF(MAX(1,CEILING(INDEX(Plan!$C$13:$C$23,MIN((MATCH($B$5,Plan!$C$13:$C$23,1)+4),11))/Plan!$C$8,1))<=200,Plan!$C$6+(Plan!$C$7-Plan!$C$6)*(MAX(1,CEILING(INDEX(Plan!$C$13:$C$23,MIN((MATCH($B$5,Plan!$C$13:$C$23,1)+4),11))/Plan!$C$8,1))-100)/100,Plan!$C$7))+SUMPRODUCT((INDEX(Plan!$C$13:$C$23,MIN((MATCH($B$5,Plan!$C$13:$C$23,1)+4),11))>=Plan!$C$13:$C$23)*Plan!$D$13:$D$23))-(($B$5*IF(MAX(1,CEILING($B$5/Plan!$C$8,1))<=100,Plan!$C$5+(Plan!$C$6-Plan!$C$5)*(MAX(1,CEILING($B$5/Plan!$C$8,1))-1)/99,IF(MAX(1,CEILING($B$5/Plan!$C$8,1))<=200,Plan!$C$6+(Plan!$C$7-Plan!$C$6)*(MAX(1,CEILING($B$5/Plan!$C$8,1))-100)/100,Plan!$C$7)))+SUMPRODUCT(($B$5>=Plan!$C$13:$C$23)*Plan!$D$13:$D$23)))} -> 59530.909 | E27: {=IF(((MATCH($B$5,Plan!$C$13:$C$23,1)+4)>11),"",INDEX(Plan!$C$13:$C$23,MIN((MATCH($B$5,Plan!$C$13:$C$23,1)+4),11))-$B$5)} -> 448000
A28: {=IF(((MATCH($B$5,Plan!$C$13:$C$23,1)+5)>11),"— at top",INDEX(Plan!$B$13:$B$23,(MATCH($B$5,Plan!$C$13:$C$23,1)+5)))} -> Senior Sales Director | B28: {=IF(((MATCH($B$5,Plan!$C$13:$C$23,1)+5)>11),"",INDEX(Plan!$C$13:$C$23,MIN((MATCH($B$5,Plan!$C$13:$C$23,1)+5),11)))} -> 700000 | C28: {=IF(((MATCH($B$5,Plan!$C$13:$C$23,1)+5)>11),"",(INDEX(Plan!$C$13:$C$23,MIN((MATCH($B$5,Plan!$C$13:$C$23,1)+5),11))*IF(MAX(1,CEILING(INDEX(Plan!$C$13:$C$23,MIN((MATCH($B$5,Plan!$C$13:$C$23,1)+5),11))/Plan!$C$8,1))<=100,Plan!$C$5+(Plan!$C$6-Plan!$C$5)*(MAX(1,CEILING(INDEX(Plan!$C$13:$C$23,MIN((MATCH($B$5,Plan!$C$13:$C$23,1)+5),11))/Plan!$C$8,1))-1)/99,IF(MAX(1,CEILING(INDEX(Plan!$C$13:$C$23,MIN((MATCH($B$5,Plan!$C$13:$C$23,1)+5),11))/Plan!$C$8,1))<=200,Plan!$C$6+(Plan!$C$7-Plan!$C$6)*(MAX(1,CEILING(INDEX(Plan!$C$13:$C$23,MIN((MATCH($B$5,Plan!$C$13:$C$23,1)+5),11))/Plan!$C$8,1))-100)/100,Plan!$C$7))+SUMPRODUCT((INDEX(Plan!$C$13:$C$23,MIN((MATCH($B$5,Plan!$C$13:$C$23,1)+5),11))>=Plan!$C$13:$C$23)*Plan!$D$13:$D$23)))} -> 99272.727 | D28: {=IF(((MATCH($B$5,Plan!$C$13:$C$23,1)+5)>11),"",(INDEX(Plan!$C$13:$C$23,MIN((MATCH($B$5,Plan!$C$13:$C$23,1)+5),11))*IF(MAX(1,CEILING(INDEX(Plan!$C$13:$C$23,MIN((MATCH($B$5,Plan!$C$13:$C$23,1)+5),11))/Plan!$C$8,1))<=100,Plan!$C$5+(Plan!$C$6-Plan!$C$5)*(MAX(1,CEILING(INDEX(Plan!$C$13:$C$23,MIN((MATCH($B$5,Plan!$C$13:$C$23,1)+5),11))/Plan!$C$8,1))-1)/99,IF(MAX(1,CEILING(INDEX(Plan!$C$13:$C$23,MIN((MATCH($B$5,Plan!$C$13:$C$23,1)+5),11))/Plan!$C$8,1))<=200,Plan!$C$6+(Plan!$C$7-Plan!$C$6)*(MAX(1,CEILING(INDEX(Plan!$C$13:$C$23,MIN((MATCH($B$5,Plan!$C$13:$C$23,1)+5),11))/Plan!$C$8,1))-100)/100,Plan!$C$7))+SUMPRODUCT((INDEX(Plan!$C$13:$C$23,MIN((MATCH($B$5,Plan!$C$13:$C$23,1)+5),11))>=Plan!$C$13:$C$23)*Plan!$D$13:$D$23))-(($B$5*IF(MAX(1,CEILING($B$5/Plan!$C$8,1))<=100,Plan!$C$5+(Plan!$C$6-Plan!$C$5)*(MAX(1,CEILING($B$5/Plan!$C$8,1))-1)/99,IF(MAX(1,CEILING($B$5/Plan!$C$8,1))<=200,Plan!$C$6+(Plan!$C$7-Plan!$C$6)*(MAX(1,CEILING($B$5/Plan!$C$8,1))-100)/100,Plan!$C$7)))+SUMPRODUCT(($B$5>=Plan!$C$13:$C$23)*Plan!$D$13:$D$23)))} -> 93955.152 | E28: {=IF(((MATCH($B$5,Plan!$C$13:$C$23,1)+5)>11),"",INDEX(Plan!$C$13:$C$23,MIN((MATCH($B$5,Plan!$C$13:$C$23,1)+5),11))-$B$5)} -> 648000
A29: Note: Because the rate climbs and applies to total sales-to-date (retroactive whole-amount), every additional $10K closed re-rates everything sold so far. That is why 'More $ Than Now' grows faster than 'Sales To Get There' as the rep climbs.

Sheet Increment Schedule
A1: Increment Schedule — every $10K of sales, with status, rate, and cumulative payout
A2: Each row represents one $10K band of sales. The rate climbs band-by-band and applies to the rep's entire balance, so each new band also produces a re-rate uplift on prior sales. Gold rows = a status bonus fires.
A4: # | B4: Sales ($) | C4: Status | D4: Rate | E4: New $10K Earns | F4: Re-rate Uplift on Prior | G4: Status Bonus | H4: Δ Payout (this step) | I4: Total Payout | K4: cum bonus
A5: 1 | B5: =1*Plan!$C$8 -> 10000 | C5: {=INDEX(Plan!$B$13:$B$23,MATCH(B5,Plan!$C$13:$C$23,1))} -> Associate | D5: =IF(A5<=100,Plan!$C$5+(Plan!$C$6-Plan!$C$5)*(A5-1)/99,IF(A5<=200,Plan!$C$6+(Plan!$C$7-Plan!$C$6)*(A5-100)/100,Plan!$C$7)) -> 0.08 | E5: =D5*Plan!$C$8 -> 800 | F5: 0 | G5: =K5 -> 0 | H5: =E5+F5+G5 -> 800 | I5: =B5*D5+K5 -> 800 | K5: =SUMPRODUCT((B5>=Plan!$C$13:$C$23)*Plan!$D$13:$D$23) -> 0
A6: 2 | B6: =2*Plan!$C$8 -> 20000 | C6: {=INDEX(Plan!$B$13:$B$23,MATCH(B6,Plan!$C$13:$C$23,1))} -> Associate | D6: =IF(A6<=100,Plan!$C$5+(Plan!$C$6-Plan!$C$5)*(A6-1)/99,IF(A6<=200,Plan!$C$6+(Plan!$C$7-Plan!$C$6)*(A6-100)/100,Plan!$C$7)) -> 0.080606061 | E6: =D6*Plan!$C$8 -> 806.06061 | F6: =B5*(D6-D5) -> 6.0606061 | G6: =K6-K5 -> 0 | H6: =E6+F6+G6 -> 812.12121 | I6: =B6*D6+K6 -> 1612.1212 | K6: =SUMPRODUCT((B6>=Plan!$C$13:$C$23)*Plan!$D$13:$D$23) -> 0
A7: 3 | B7: =3*Plan!$C$8 -> 30000 | C7: {=INDEX(Plan!$B$13:$B$23,MATCH(B7,Plan!$C$13:$C$23,1))} -> Associate | D7: =IF(A7<=100,Plan!$C$5+(Plan!$C$6-Plan!$C$5)*(A7-1)/99,IF(A7<=200,Plan!$C$6+(Plan!$C$7-Plan!$C$6)*(A7-100)/100,Plan!$C$7)) -> 0.081212121 | E7: =D7*Plan!$C$8 -> 812.12121 | F7: =B6*(D7-D6) -> 12.121212 | G7: =K7-K6 -> 0 | H7: =E7+F7+G7 -> 824.24242 | I7: =B7*D7+K7 -> 2436.3636 | K7: =SUMPRODUCT((B7>=Plan!$C$13:$C$23)*Plan!$D$13:$D$23) -> 0
A8: 4 | B8: =4*Plan!$C$8 -> 40000 | C8: {=INDEX(Plan!$B$13:$B$23,MATCH(B8,Plan!$C$13:$C$23,1))} -> Associate | D8: =IF(A8<=100,Plan!$C$5+(Plan!$C$6-Plan!$C$5)*(A8-1)/99,IF(A8<=200,Plan!$C$6+(Plan!$C$7-Plan!$C$6)*(A8-100)/100,Plan!$C$7)) -> 0.081818182 | E8: =D8*Plan!$C$8 -> 818.18182 | F8: =B7*(D8-D7) -> 18.181818 | G8: =K8-K7 -> 0 | H8: =E8+F8+G8 -> 836.36364 | I8: =B8*D8+K8 -> 3272.7273 | K8: =SUMPRODUCT((B8>=Plan!$C$13:$C$23)*Plan!$D$13:$D$23) -> 0
A9: 5 | B9: =5*Plan!$C$8 -> 50000 | C9: {=INDEX(Plan!$B$13:$B$23,MATCH(B9,Plan!$C$13:$C$23,1))} -> Account Executive | D9: =IF(A9<=100,Plan!$C$5+(Plan!$C$6-Plan!$C$5)*(A9-1)/99,IF(A9<=200,Plan!$C$6+(Plan!$C$7-Plan!$C$6)*(A9-100)/100,Plan!$C$7)) -> 0.082424242 | E9: =D9*Plan!$C$8 -> 824.24242 | F9: =B8*(D9-D8) -> 24.242424 | G9: =K9-K8 -> 1000 | H9: =E9+F9+G9 -> 1848.4848 | I9: =B9*D9+K9 -> 5121.2121 | K9: =SUMPRODUCT((B9>=Plan!$C$13:$C$23)*Plan!$D$13:$D$23) -> 1000
A10: 6 | B10: =6*Plan!$C$8 -> 60000 | C10: {=INDEX(Plan!$B$13:$B$23,MATCH(B10,Plan!$C$13:$C$23,1))} -> Account Executive | D10: =IF(A10<=100,Plan!$C$5+(Plan!$C$6-Plan!$C$5)*(A10-1)/99,IF(A10<=200,Plan!$C$6+(Plan!$C$7-Plan!$C$6)*(A10-100)/100,Plan!$C$7)) -> 0.083030303 | E10: =D10*Plan!$C$8 -> 830.30303 | F10: =B9*(D10-D9) -> 30.30303 | G10: =K10-K9 -> 0 | H10: =E10+F10+G10 -> 860.60606 | I10: =B10*D10+K10 -> 5981.8182 | K10: =SUMPRODUCT((B10>=Plan!$C$13:$C$23)*Plan!$D$13:$D$23) -> 1000
A11: 7 | B11: =7*Plan!$C$8 -> 70000 | C11: {=INDEX(Plan!$B$13:$B$23,MATCH(B11,Plan!$C$13:$C$23,1))} -> Account Executive | D11: =IF(A11<=100,Plan!$C$5+(Plan!$C$6-Plan!$C$5)*(A11-1)/99,IF(A11<=200,Plan!$C$6+(Plan!$C$7-Plan!$C$6)*(A11-100)/100,Plan!$C$7)) -> 0.083636364 | E11: =D11*Plan!$C$8 -> 836.36364 | F11: =B10*(D11-D10) -> 36.363636 | G11: =K11-K10 -> 0 | H11: =E11+F11+G11 -> 872.72727 | I11: =B11*D11+K11 -> 6854.5455 | K11: =SUMPRODUCT((B11>=Plan!$C$13:$C$23)*Plan!$D$13:$D$23) -> 1000
A12: 8 | B12: =8*Plan!$C$8 -> 80000 | C12: {=INDEX(Plan!$B$13:$B$23,MATCH(B12,Plan!$C$13:$C$23,1))} -> Account Executive | D12: =IF(A12<=100,Plan!$C$5+(Plan!$C$6-Plan!$C$5)*(A12-1)/99,IF(A12<=200,Plan!$C$6+(Plan!$C$7-Plan!$C$6)*(A12-100)/100,Plan!$C$7)) -> 0.084242424 | E12: =D12*Plan!$C$8 -> 842.42424 | F12: =B11*(D12-D11) -> 42.424242 | G12: =K12-K11 -> 0 | H12: =E12+F12+G12 -> 884.84848 | I12: =B12*D12+K12 -> 7739.3939 | K12: =SUMPRODUCT((B12>=Plan!$C$13:$C$23)*Plan!$D$13:$D$23) -> 1000
A13: 9 | B13: =9*Plan!$C$8 -> 90000 | C13: {=INDEX(Plan!$B$13:$B$23,MATCH(B13,Plan!$C$13:$C$23,1))} -> Account Executive | D13: =IF(A13<=100,Plan!$C$5+(Plan!$C$6-Plan!$C$5)*(A13-1)/99,IF(A13<=200,Plan!$C$6+(Plan!$C$7-Plan!$C$6)*(A13-100)/100,Plan!$C$7)) -> 0.084848485 | E13: =D13*Plan!$C$8 -> 848.48485 | F13: =B12*(D13-D12) -> 48.484848 | G13: =K13-K12 -> 0 | H13: =E13+F13+G13 -> 896.9697 | I13: =B13*D13+K13 -> 8636.3636 | K13: =SUMPRODUCT((B13>=Plan!$C$13:$C$23)*Plan!$D$13:$D$23) -> 1000
A14: 10 | B14: =10*Plan!$C$8 -> 100000 | C14: {=INDEX(Plan!$B$13:$B$23,MATCH(B14,Plan!$C$13:$C$23,1))} -> Account Executive | D14: =IF(A14<=100,Plan!$C$5+(Plan!$C$6-Plan!$C$5)*(A14-1)/99,IF(A14<=200,Plan!$C$6+(Plan!$C$7-Plan!$C$6)*(A14-100)/100,Plan!$C$7)) -> 0.085454545 | E14: =D14*Plan!$C$8 -> 854.54545 | F14: =B13*(D14-D13) -> 54.545455 | G14: =K14-K13 -> 0 | H14: =E14+F14+G14 -> 909.09091 | I14: =B14*D14+K14 -> 9545.4545 | K14: =SUMPRODUCT((B14>=Plan!$C$13:$C$23)*Plan!$D$13:$D$23) -> 1000
A15: 11 | B15: =11*Plan!$C$8 -> 110000 | C15: {=INDEX(Plan!$B$13:$B$23,MATCH(B15,Plan!$C$13:$C$23,1))} -> Account Executive | D15: =IF(A15<=100,Plan!$C$5+(Plan!$C$6-Plan!$C$5)*(A15-1)/99,IF(A15<=200,Plan!$C$6+(Plan!$C$7-Plan!$C$6)*(A15-100)/100,Plan!$C$7)) -> 0.086060606 | E15: =D15*Plan!$C$8 -> 860.60606 | F15: =B14*(D15-D14) -> 60.606061 | G15: =K15-K14 -> 0 | H15: =E15+F15+G15 -> 921.21212 | I15: =B15*D15+K15 -> 10466.667 | K15: =SUMPRODUCT((B15>=Plan!$C$13:$C$23)*Plan!$D$13:$D$23) -> 1000
A16: 12 | B16: =12*Plan!$C$8 -> 120000 | C16: {=INDEX(Plan!$B$13:$B$23,MATCH(B16,Plan!$C$13:$C$23,1))} -> Account Executive | D16: =IF(A16<=100,Plan!$C$5+(Plan!$C$6-Plan!$C$5)*(A16-1)/99,IF(A16<=200,Plan!$C$6+(Plan!$C$7-Plan!$C$6)*(A16-100)/100,Plan!$C$7)) -> 0.086666667 | E16: =D16*Plan!$C$8 -> 866.66667 | F16: =B15*(D16-D15) -> 66.666667 | G16: =K16-K15 -> 0 | H16: =E16+F16+G16 -> 933.33333 | I16: =B16*D16+K16 -> 11400 | K16: =SUMPRODUCT((B16>=Plan!$C$13:$C$23)*Plan!$D$13:$D$23) -> 1000
A17: 13 | B17: =13*Plan!$C$8 -> 130000 | C17: {=INDEX(Plan!$B$13:$B$23,MATCH(B17,Plan!$C$13:$C$23,1))} -> Senior Account Executive | D17: =IF(A17<=100,Plan!$C$5+(Plan!$C$6-Plan!$C$5)*(A17-1)/99,IF(A17<=200,Plan!$C$6+(Plan!$C$7-Plan!$C$6)*(A17-100)/100,Plan!$C$7)) -> 0.087272727 | E17: =D17*Plan!$C$8 -> 872.72727 | F17: =B16*(D17-D16) -> 72.727273 | G17: =K17-K16 -> 1500 | H17: =E17+F17+G17 -> 2445.4545 | I17: =B17*D17+K17 -> 13845.455 | K17: =SUMPRODUCT((B17>=Plan!$C$13:$C$23)*Plan!$D$13:$D$23) -> 2500
A18: 14 | B18: =14*Plan!$C$8 -> 140000 | C18: {=INDEX(Plan!$B$13:$B$23,MATCH(B18,Plan!$C$13:$C$23,1))} -> Senior Account Executive | D18: =IF(A18<=100,Plan!$C$5+(Plan!$C$6-Plan!$C$5)*(A18-1)/99,IF(A18<=200,Plan!$C$6+(Plan!$C$7-Plan!$C$6)*(A18-100)/100,Plan!$C$7)) -> 0.087878788 | E18: =D18*Plan!$C$8 -> 878.78788 | F18: =B17*(D18-D17) -> 78.787879 | G18: =K18-K17 -> 0 | H18: =E18+F18+G18 -> 957.57576 | I18: =B18*D18+K18 -> 14803.03 | K18: =SUMPRODUCT((B18>=Plan!$C$13:$C$23)*Plan!$D$13:$D$23) -> 2500
A19: 15 | B19: =15*Plan!$C$8 -> 150000 | C19: {=INDEX(Plan!$B$13:$B$23,MATCH(B19,Plan!$C$13:$C$23,1))} -> Senior Account Executive | D19: =IF(A19<=100,Plan!$C$5+(Plan!$C$6-Plan!$C$5)*(A19-1)/99,IF(A19<=200,Plan!$C$6+(Plan!$C$7-Plan!$C$6)*(A19-100)/100,Plan!$C$7)) -> 0.088484848 | E19: =D19*Plan!$C$8 -> 884.84848 | F19: =B18*(D19-D18) -> 84.848485 | G19: =K19-K18 -> 0 | H19: =E19+F19+G19 -> 969.69697 | I19: =B19*D19+K19 -> 15772.727 | K19: =SUMPRODUCT((B19>=Plan!$C$13:$C$23)*Plan!$D$13:$D$23) -> 2500
A20: 16 | B20: =16*Plan!$C$8 -> 160000 | C20: {=INDEX(Plan!$B$13:$B$23,MATCH(B20,Plan!$C$13:$C$23,1))} -> Senior Account Executive | D20: =IF(A20<=100,Plan!$C$5+(Plan!$C$6-Plan!$C$5)*(A20-1)/99,IF(A20<=200,Plan!$C$6+(Plan!$C$7-Plan!$C$6)*(A20-100)/100,Plan!$C$7)) -> 0.089090909 | E20: =D20*Plan!$C$8 -> 890.90909 | F20: =B19*(D20-D19) -> 90.909091 | G20: =K20-K19 -> 0 | H20: =E20+F20+G20 -> 981.81818 | I20: =B20*D20+K20 -> 16754.545 | K20: =SUMPRODUCT((B20>=Plan!$C$13:$C$23)*Plan!$D$13:$D$23) -> 2500
A21: 17 | B21: =17*Plan!$C$8 -> 170000 | C21: {=INDEX(Plan!$B$13:$B$23,MATCH(B21,Plan!$C$13:$C$23,1))} -> Senior Account Executive | D21: =IF(A21<=100,Plan!$C$5+(Plan!$C$6-Plan!$C$5)*(A21-1)/99,IF(A21<=200,Plan!$C$6+(Plan!$C$7-Plan!$C$6)*(A21-100)/100,Plan!$C$7)) -> 0.08969697 | E21: =D21*Plan!$C$8 -> 896.9697 | F21: =B20*(D21-D20) -> 96.969697 | G21: =K21-K20 -> 0 | H21: =E21+F21+G21 -> 993.93939 | I21: =B21*D21+K21 -> 17748.485 | K21: =SUMPRODUCT((B21>=Plan!$C$13:$C$23)*Plan!$D$13:$D$23) -> 2500
A22: 18 | B22: =18*Plan!$C$8 -> 180000 | C22: {=INDEX(Plan!$B$13:$B$23,MATCH(B22,Plan!$C$13:$C$23,1))} -> Senior Account Executive | D22: =IF(A22<=100,Plan!$C$5+(Plan!$C$6-Plan!$C$5)*(A22-1)/99,IF(A22<=200,Plan!$C$6+(Plan!$C$7-Plan!$C$6)*(A22-100)/100,Plan!$C$7)) -> 0.09030303 | E22: =D22*Plan!$C$8 -> 903.0303 | F22: =B21*(D22-D21) -> 103.0303 | G22: =K22-K21 -> 0 | H22: =E22+F22+G22 -> 1006.0606 | I22: =B22*D22+K22 -> 18754.545 | K22: =SUMPRODUCT((B22>=Plan!$C$13:$C$23)*Plan!$D$13:$D$23) -> 2500
A23: 19 | B23: =19*Plan!$C$8 -> 190000 | C23: {=INDEX(Plan!$B$13:$B$23,MATCH(B23,Plan!$C$13:$C$23,1))} -> Senior Account Executive | D23: =IF(A23<=100,Plan!$C$5+(Plan!$C$6-Plan!$C$5)*(A23-1)/99,IF(A23<=200,Plan!$C$6+(Plan!$C$7-Plan!$C$6)*(A23-100)/100,Plan!$C$7)) -> 0.090909091 | E23: =D23*Plan!$C$8 -> 909.09091 | F23: =B22*(D23-D22) -> 109.09091 | G23: =K23-K22 -> 0 | H23: =E23+F23+G23 -> 1018.1818 | I23: =B23*D23+K23 -> 19772.727 | K23: =SUMPRODUCT((B23>=Plan!$C$13:$C$23)*Plan!$D$13:$D$23) -> 2500
A24: 20 | B24: =20*Plan!$C$8 -> 200000 | C24: {=INDEX(Plan!$B$13:$B$23,MATCH(B24,Plan!$C$13:$C$23,1))} -> Senior Account Executive | D24: =IF(A24<=100,Plan!$C$5+(Plan!$C$6-Plan!$C$5)*(A24-1)/99,IF(A24<=200,Plan!$C$6+(Plan!$C$7-Plan!$C$6)*(A24-100)/100,Plan!$C$7)) -> 0.091515152 | E24: =D24*Plan!$C$8 -> 915.15152 | F24: =B23*(D24-D23) -> 115.15152 | G24: =K24-K23 -> 0 | H24: =E24+F24+G24 -> 1030.303 | I24: =B24*D24+K24 -> 20803.03 | K24: =SUMPRODUCT((B24>=Plan!$C$13:$C$23)*Plan!$D$13:$D$23) -> 2500
A25: 21 | B25: =21*Plan!$C$8 -> 210000 | C25: {=INDEX(Plan!$B$13:$B$23,MATCH(B25,Plan!$C$13:$C$23,1))} -> Senior Account Executive | D25: =IF(A25<=100,Plan!$C$5+(Plan!$C$6-Plan!$C$5)*(A25-1)/99,IF(A25<=200,Plan!$C$6+(Plan!$C$7-Plan!$C$6)*(A25-100)/100,Plan!$C$7)) -> 0.092121212 | E25: =D25*Plan!$C$8 -> 921.21212 | F25: =B24*(D25-D24) -> 121.21212 | G25: =K25-K24 -> 0 | H25: =E25+F25+G25 -> 1042.4242 | I25: =B25*D25+K25 -> 21845.455 | K25: =SUMPRODUCT((B25>=Plan!$C$13:$C$23)*Plan!$D$13:$D$23) -> 2500
A26: 22 | B26: =22*Plan!$C$8 -> 220000 | C26: {=INDEX(Plan!$B$13:$B$23,MATCH(B26,Plan!$C$13:$C$23,1))} -> Senior Account Executive | D26: =IF(A26<=100,Plan!$C$5+(Plan!$C$6-Plan!$C$5)*(A26-1)/99,IF(A26<=200,Plan!$C$6+(Plan!$C$7-Plan!$C$6)*(A26-100)/100,Plan!$C$7)) -> 0.092727273 | E26: =D26*Plan!$C$8 -> 927.27273 | F26: =B25*(D26-D25) -> 127.27273 | G26: =K26-K25 -> 0 | H26: =E26+F26+G26 -> 1054.5455 | I26: =B26*D26+K26 -> 22900 | K26: =SUMPRODUCT((B26>=Plan!$C$13:$C$23)*Plan!$D$13:$D$23) -> 2500
A27: 23 | B27: =23*Plan!$C$8 -> 230000 | C27: {=INDEX(Plan!$B$13:$B$23,MATCH(B27,Plan!$C$13:$C$23,1))} -> Account Director | D27: =IF(A27<=100,Plan!$C$5+(Plan!$C$6-Plan!$C$5)*(A27-1)/99,IF(A27<=200,Plan!$C$6+(Plan!$C$7-Plan!$C$6)*(A27-100)/100,Plan!$C$7)) -> 0.093333333 | E27: =D27*Plan!$C$8 -> 933.33333 | F27: =B26*(D27-D26) -> 133.33333 | G27: =K27-K26 -> 2000 | H27: =E27+F27+G27 -> 3066.6667 | I27: =B27*D27+K27 -> 25966.667 | K27: =SUMPRODUCT((B27>=Plan!$C$13:$C$23)*Plan!$D$13:$D$23) -> 4500
A28: 24 | B28: =24*Plan!$C$8 -> 240000 | C28: {=INDEX(Plan!$B$13:$B$23,MATCH(B28,Plan!$C$13:$C$23,1))} -> Account Director | D28: =IF(A28<=100,Plan!$C$5+(Plan!$C$6-Plan!$C$5)*(A28-1)/99,IF(A28<=200,Plan!$C$6+(Plan!$C$7-Plan!$C$6)*(A28-100)/100,Plan!$C$7)) -> 0.093939394 | E28: =D28*Plan!$C$8 -> 939.39394 | F28: =B27*(D28-D27) -> 139.39394 | G28: =K28-K27 -> 0 | H28: =E28+F28+G28 -> 1078.7879 | I28: =B28*D28+K28 -> 27045.455 | K28: =SUMPRODUCT((B28>=Plan!$C$13:$C$23)*Plan!$D$13:$D$23) -> 4500
A29: 25 | B29: =25*Plan!$C$8 -> 250000 | C29: {=INDEX(Plan!$B$13:$B$23,MATCH(B29,Plan!$C$13:$C$23,1))} -> Account Director | D29: =IF(A29<=100,Plan!$C$5+(Plan!$C$6-Plan!$C$5)*(A29-1)/99,IF(A29<=200,Plan!$C$6+(Plan!$C$7-Plan!$C$6)*(A29-100)/100,Plan!$C$7)) -> 0.094545455 | E29: =D29*Plan!$C$8 -> 945.45455 | F29: =B28*(D29-D28) -> 145.45455 | G29: =K29-K28 -> 0 | H29: =E29+F29+G29 -> 1090.9091 | I29: =B29*D29+K29 -> 28136.364 | K29: =SUMPRODUCT((B29>=Plan!$C$13:$C$23)*Plan!$D$13:$D$23) -> 4500
A30: 26 | B30: =26*Plan!$C$8 -> 260000 | C30: {=INDEX(Plan!$B$13:$B$23,MATCH(B30,Plan!$C$13:$C$23,1))} -> Account Director | D30: =IF(A30<=100,Plan!$C$5+(Plan!$C$6-Plan!$C$5)*(A30-1)/99,IF(A30<=200,Plan!$C$6+(Plan!$C$7-Plan!$C$6)*(A30-100)/100,Plan!$C$7)) -> 0.095151515 | E30: =D30*Plan!$C$8 -> 951.51515 | F30: =B29*(D30-D29) -> 151.51515 | G30: =K30-K29 -> 0 | H30: =E30+F30+G30 -> 1103.0303 | I30: =B30*D30+K30 -> 29239.394 | K30: =SUMPRODUCT((B30>=Plan!$C$13:$C$23)*Plan!$D$13:$D$23) -> 4500
A31: 27 | B31: =27*Plan!$C$8 -> 270000 | C31: {=INDEX(Plan!$B$13:$B$23,MATCH(B31,Plan!$C$13:$C$23,1))} -> Account Director | D31: =IF(A31<=100,Plan!$C$5+(Plan!$C$6-Plan!$C$5)*(A31-1)/99,IF(A31<=200,Plan!$C$6+(Plan!$C$7-Plan!$C$6)*(A31-100)/100,Plan!$C$7)) -> 0.095757576 | E31: =D31*Plan!$C$8 -> 957.57576 | F31: =B30*(D31-D30) -> 157.57576 | G31: =K31-K30 -> 0 | H31: =E31+F31+G31 -> 1115.1515 | I31: =B31*D31+K31 -> 30354.545 | K31: =SUMPRODUCT((B31>=Plan!$C$13:$C$23)*Plan!$D$13:$D$23) -> 4500
A32: 28 | B32: =28*Plan!$C$8 -> 280000 | C32: {=INDEX(Plan!$B$13:$B$23,MATCH(B32,Plan!$C$13:$C$23,1))} -> Account Director | D32: =IF(A32<=100,Plan!$C$5+(Plan!$C$6-Plan!$C$5)*(A32-1)/99,IF(A32<=200,Plan!$C$6+(Plan!$C$7-Plan!$C$6)*(A32-100)/100,Plan!$C$7)) -> 0.096363636 | E32: =D32*Plan!$C$8 -> 963.63636 | F32: =B31*(D32-D31) -> 163.63636 | G32: =K32-K31 -> 0 | H32: =E32+F32+G32 -> 1127.2727 | I32: =B32*D32+K32 -> 31481.818 | K32: =SUMPRODUCT((B32>=Plan!$C$13:$C$23)*Plan!$D$13:$D$23) -> 4500
A33: 29 | B33: =29*Plan!$C$8 -> 290000 | C33: {=INDEX(Plan!$B$13:$B$23,MATCH(B33,Plan!$C$13:$C$23,1))} -> Account Director | D33: =IF(A33<=100,Plan!$C$5+(Plan!$C$6-Plan!$C$5)*(A33-1)/99,IF(A33<=200,Plan!$C$6+(Plan!$C$7-Plan!$C$6)*(A33-100)/100,Plan!$C$7)) -> 0.096969697 | E33: =D33*Plan!$C$8 -> 969.69697 | F33: =B32*(D33-D32) -> 169.69697 | G33: =K33-K32 -> 0 | H33: =E33+F33+G33 -> 1139.3939 | I33: =B33*D33+K33 -> 32621.212 | K33: =SUMPRODUCT((B33>=Plan!$C$13:$C$23)*Plan!$D$13:$D$23) -> 4500
A34: 30 | B34: =30*Plan!$C$8 -> 300000 | C34: {=INDEX(Plan!$B$13:$B$23,MATCH(B34,Plan!$C$13:$C$23,1))} -> Account Director | D34: =IF(A34<=100,Plan!$C$5+(Plan!$C$6-Plan!$C$5)*(A34-1)/99,IF(A34<=200,Plan!$C$6+(Plan!$C$7-Plan!$C$6)*(A34-100)/100,Plan!$C$7)) -> 0.097575758 | E34: =D34*Plan!$C$8 -> 975.75758 | F34: =B33*(D34-D33) -> 175.75758 | G34: =K34-K33 -> 0 | H34: =E34+F34+G34 -> 1151.5152 | I34: =B34*D34+K34 -> 33772.727 | K34: =SUMPRODUCT((B34>=Plan!$C$13:$C$23)*Plan!$D$13:$D$23) -> 4500
A35: 31 | B35: =31*Plan!$C$8 -> 310000 | C35: {=INDEX(Plan!$B$13:$B$23,MATCH(B35,Plan!$C$13:$C$23,1))} -> Account Director | D35: =IF(A35<=100,Plan!$C$5+(Plan!$C$6-Plan!$C$5)*(A35-1)/99,IF(A35<=200,Plan!$C$6+(Plan!$C$7-Plan!$C$6)*(A35-100)/100,Plan!$C$7)) -> 0.098181818 | E35: =D35*Plan!$C$8 -> 981.81818 | F35: =B34*(D35-D34) -> 181.81818 | G35: =K35-K34 -> 0 | H35: =E35+F35+G35 -> 1163.6364 | I35: =B35*D35+K35 -> 34936.364 | K35: =SUMPRODUCT((B35>=Plan!$C$13:$C$23)*Plan!$D$13:$D$23) -> 4500
A36: 32 | B36: =32*Plan!$C$8 -> 320000 | C36: {=INDEX(Plan!$B$13:$B$23,MATCH(B36,Plan!$C$13:$C$23,1))} -> Account Director | D36: =IF(A36<=100,Plan!$C$5+(Plan!$C$6-Plan!$C$5)*(A36-1)/99,IF(A36<=200,Plan!$C$6+(Plan!$C$7-Plan!$C$6)*(A36-100)/100,Plan!$C$7)) -> 0.098787879 | E36: =D36*Plan!$C$8 -> 987.87879 | F36: =B35*(D36-D35) -> 187.87879 | G36: =K36-K35 -> 0 | H36: =E36+F36+G36 -> 1175.7576 | I36: =B36*D36+K36 -> 36112.121 | K36: =SUMPRODUCT((B36>=Plan!$C$13:$C$23)*Plan!$D$13:$D$23) -> 4500
A37: 33 | B37: =33*Plan!$C$8 -> 330000 | C37: {=INDEX(Plan!$B$13:$B$23,MATCH(B37,Plan!$C$13:$C$23,1))} -> Account Director | D37: =IF(A37<=100,Plan!$C$5+(Plan!$C$6-Plan!$C$5)*(A37-1)/99,IF(A37<=200,Plan!$C$6+(Plan!$C$7-Plan!$C$6)*(A37-100)/100,Plan!$C$7)) -> 0.099393939 | E37: =D37*Plan!$C$8 -> 993.93939 | F37: =B36*(D37-D36) -> 193.93939 | G37: =K37-K36 -> 0 | H37: =E37+F37+G37 -> 1187.8788 | I37: =B37*D37+K37 -> 37300 | K37: =SUMPRODUCT((B37>=Plan!$C$13:$C$23)*Plan!$D$13:$D$23) -> 4500
A38: 34 | B38: =34*Plan!$C$8 -> 340000 | C38: {=INDEX(Plan!$B$13:$B$23,MATCH(B38,Plan!$C$13:$C$23,1))} -> Account Director | D38: =IF(A38<=100,Plan!$C$5+(Plan!$C$6-Plan!$C$5)*(A38-1)/99,IF(A38<=200,Plan!$C$6+(Plan!$C$7-Plan!$C$6)*(A38-100)/100,Plan!$C$7)) -> 0.1 | E38: =D38*Plan!$C$8 -> 1000 | F38: =B37*(D38-D37) -> 200 | G38: =K38-K37 -> 0 | H38: =E38+F38+G38 -> 1200 | I38: =B38*D38+K38 -> 38500 | K38: =SUMPRODUCT((B38>=Plan!$C$13:$C$23)*Plan!$D$13:$D$23) -> 4500
A39: 35 | B39: =35*Plan!$C$8 -> 350000 | C39: {=INDEX(Plan!$B$13:$B$23,MATCH(B39,Plan!$C$13:$C$23,1))} -> Senior Account Director | D39: =IF(A39<=100,Plan!$C$5+(Plan!$C$6-Plan!$C$5)*(A39-1)/99,IF(A39<=200,Plan!$C$6+(Plan!$C$7-Plan!$C$6)*(A39-100)/100,Plan!$C$7)) -> 0.10060606 | E39: =D39*Plan!$C$8 -> 1006.0606 | F39: =B38*(D39-D38) -> 206.06061 | G39: =K39-K38 -> 2500 | H39: =E39+F39+G39 -> 3712.1212 | I39: =B39*D39+K39 -> 42212.121 | K39: =SUMPRODUCT((B39>=Plan!$C$13:$C$23)*Plan!$D$13:$D$23) -> 7000
A40: 36 | B40: =36*Plan!$C$8 -> 360000 | C40: {=INDEX(Plan!$B$13:$B$23,MATCH(B40,Plan!$C$13:$C$23,1))} -> Senior Account Director | D40: =IF(A40<=100,Plan!$C$5+(Plan!$C$6-Plan!$C$5)*(A40-1)/99,IF(A40<=200,Plan!$C$6+(Plan!$C$7-Plan!$C$6)*(A40-100)/100,Plan!$C$7)) -> 0.10121212 | E40: =D40*Plan!$C$8 -> 1012.1212 | F40: =B39*(D40-D39) -> 212.12121 | G40: =K40-K39 -> 0 | H40: =E40+F40+G40 -> 1224.2424 | I40: =B40*D40+K40 -> 43436.364 | K40: =SUMPRODUCT((B40>=Plan!$C$13:$C$23)*Plan!$D$13:$D$23) -> 7000
A41: 37 | B41: =37*Plan!$C$8 -> 370000 | C41: {=INDEX(Plan!$B$13:$B$23,MATCH(B41,Plan!$C$13:$C$23,1))} -> Senior Account Director | D41: =IF(A41<=100,Plan!$C$5+(Plan!$C$6-Plan!$C$5)*(A41-1)/99,IF(A41<=200,Plan!$C$6+(Plan!$C$7-Plan!$C$6)*(A41-100)/100,Plan!$C$7)) -> 0.10181818 | E41: =D41*Plan!$C$8 -> 1018.1818 | F41: =B40*(D41-D40) -> 218.18182 | G41: =K41-K40 -> 0 | H41: =E41+F41+G41 -> 1236.3636 | I41: =B41*D41+K41 -> 44672.727 | K41: =SUMPRODUCT((B41>=Plan!$C$13:$C$23)*Plan!$D$13:$D$23) -> 7000
...
